2018-06-28 21:42:11,063 ERROR: Exception on /auth/login [POST] [in /home/jack/.local/share/virtualenvs/pyblog-Bk2l9Soa/lib/python3.6/site-packages/flask/app.py:1761]
Traceback (most recent call last):
  File "/home/jack/.local/share/virtualenvs/pyblog-Bk2l9Soa/lib/python3.6/site-packages/flask/app.py", line 2292, in wsgi_app
    response = self.full_dispatch_request()
  File "/home/jack/.local/share/virtualenvs/pyblog-Bk2l9Soa/lib/python3.6/site-packages/flask/app.py", line 1815, in full_dispatch_request
    rv = self.handle_user_exception(e)
  File "/home/jack/.local/share/virtualenvs/pyblog-Bk2l9Soa/lib/python3.6/site-packages/flask/app.py", line 1718, in handle_user_exception
    reraise(exc_type, exc_value, tb)
  File "/home/jack/.local/share/virtualenvs/pyblog-Bk2l9Soa/lib/python3.6/site-packages/flask/_compat.py", line 35, in reraise
    raise value
  File "/home/jack/.local/share/virtualenvs/pyblog-Bk2l9Soa/lib/python3.6/site-packages/flask/app.py", line 1813, in full_dispatch_request
    rv = self.dispatch_request()
  File "/home/jack/.local/share/virtualenvs/pyblog-Bk2l9Soa/lib/python3.6/site-packages/flask/app.py", line 1799, in dispatch_request
    return self.view_functions[rule.endpoint](**req.view_args)
  File "/home/jack/gitStore/pyblog/app/auth/routes.py", line 21, in login
    return redirect(url_for('login'))
  File "/home/jack/.local/share/virtualenvs/pyblog-Bk2l9Soa/lib/python3.6/site-packages/flask/helpers.py", line 356, in url_for
    return appctx.app.handle_url_build_error(error, endpoint, values)
  File "/home/jack/.local/share/virtualenvs/pyblog-Bk2l9Soa/lib/python3.6/site-packages/flask/app.py", line 2061, in handle_url_build_error
    reraise(exc_type, exc_value, tb)
  File "/home/jack/.local/share/virtualenvs/pyblog-Bk2l9Soa/lib/python3.6/site-packages/flask/_compat.py", line 35, in reraise
    raise value
  File "/home/jack/.local/share/virtualenvs/pyblog-Bk2l9Soa/lib/python3.6/site-packages/flask/helpers.py", line 345, in url_for
    force_external=external)
  File "/home/jack/.local/share/virtualenvs/pyblog-Bk2l9Soa/lib/python3.6/site-packages/werkzeug/routing.py", line 1776, in build
    raise BuildError(endpoint, values, method, self)
werkzeug.routing.BuildError: Could not build url for endpoint 'login'. Did you mean 'auth.login' instead?
